ERROR:root:Traceback (most recent call last):
  File "E:/operating/demo/__init__.py", line 47, in work
    browser.find_element_by_name("username").send_keys(u"ÓÃ»§Ãû")
  File "E:\Program Files\Python36\lib\site-packages\selenium\webdriver\remote\webdriver.py", line 385, in find_element_by_name
    return self.find_element(by=By.NAME, value=name)
  File "E:\Program Files\Python36\lib\site-packages\selenium\webdriver\remote\webdriver.py", line 791, in find_element
    'value': value})['value']
  File "E:\Program Files\Python36\lib\site-packages\selenium\webdriver\remote\webdriver.py", line 256, in execute
    self.error_handler.check_response(response)
  File "E:\Program Files\Python36\lib\site-packages\selenium\webdriver\remote\errorhandler.py", line 194, in check_response
    raise exception_class(message, screen, stacktrace)
selenium.common.exceptions.NoSuchElementException: Message: no such element: Unable to locate element: {"method":"name","selector":"username"}
  (Session info: chrome=59.0.3071.104)
  (Driver info: chromedriver=2.30.477700 (0057494ad8732195794a7b32078424f92a5fce41),platform=Windows NT 10.0.14393 x86_64)


